Workbook

Sheet Overview Dashboard
B2: 🎬 IMDB Top 1000 Movies — Overview Dashboard | K2: Data Source: IMDB Top 1000 | Updated: Dynamic
B5: 📊 KEY PERFORMANCE INDICATORS
B7: Total Movies | E7: Avg IMDB Rating | H7: Total Gross Revenue | K7: Avg Runtime (min)
B8: =COUNTA(RawData!A2:A10000)-COUNTIF(RawData!A2:A10000,"") -> -8653 | E8: =ROUND(AVERAGE(RawData!F2:F10000),2) -> 7.94 | H8: =SUM(RawData!N2:N10000) -> 53968015598 | K8: =ROUND(AVERAGE(RawData!O2:O10000),0) -> 124
B13: 📈 CHARTS & VISUALIZATIONS

Sheet Financial Dashboard
B2: 💰 IMDB Top 1000 — Financial & Performance Dashboard | K2: Gross Revenue & Ratings Analysis
B5: 📊 FINANCIAL KPIs
B7: Highest Gross ($) | E7: Lowest Gross ($) | H7: Avg Gross ($M) | K7: Total Gross ($B)
B8: =TEXT(MAX(RawData!N2:N10000),"$#,##0") -> $936,662,225 | E8: =TEXT(MIN(IF(RawData!N2:N10000>0,RawData!N2:N10000)),"$#,##0") -> $1,305 | H8: =ROUND(AVERAGE(RawData!N2:N10000)/1000000,2) -> 80.19 | K8: =ROUND(SUM(RawData!N2:N10000)/1000000000,2) -> 53.97
B11: 📋 PERFORMANCE METRICS
B13: Highest Grossing Movie | H13: Best Rated Movie
B14: =INDEX(RawData!A2:A10000,MATCH(MAX(RawData!N2:N10000),RawData!N2:N10000,0)) -> Star Wars: Episode VII - The Force Awakens | H14: =INDEX(RawData!A2:A10000,MATCH(MAX(RawData!F2:F10000),RawData!F2:F10000,0)) -> The Shawshank Redemption
B17: 💡 FINANCIAL INSIGHTS
B18: 📈 Rating–Gross Correlation | E18: =ROUND(CORREL(RawData!F2:F10000,RawData!N2:N10000),4) -> 0.118
B19: 🎬 Best Genre by Total Gross | E19: =INDEX(_HelperData!A:A,MATCH(MAX(_HelperData!B:B),_HelperData!B:B,0)) -> Action
B20: ⭐ Avg Gross for Action Movies | E20: =ROUND(AVERAGEIF(RawData!P2:P10000,"Action",RawData!N2:N10000),0) -> 160803113
B21: 🏅 Avg Gross for Drama Movies | E21: =ROUND(AVERAGEIF(RawData!P2:P10000,"Drama",RawData!N2:N10000),0) -> 48894875
B22: 📊 Count of $100M+ Movies | E22: =COUNTIF(RawData!N2:N10000,">100000000") -> 182
B23: 💎 Max Meta Score | E23: =MAX(RawData!G2:G10000) -> 100
B25: 📈 CHARTS & ANALYSIS

Sheet Deep Dive Analysis
C2: 🔍 IMDB Top 1000 — Deep Dive Analysis Dashboard | K2: Directors | Stars | Runtime | Certificates
B5: 📊 PEOPLE & CONTENT KPIs
B7: Unique Directors | E7: Unique Stars (All) | H7: Avg No. of Votes | K7: Avg Meta Score
B8: =COUNTA(_xludf.unique(RawData!H2:H10000)) -> 1 | E8: =COUNTA(_xludf.unique(RawData!I2:I10000))+COUNTA(_xludf.unique(RawData!J2:J10000)) -> 2 | H8: =ROUND(AVERAGE(RawData!M2:M10000),0) -> 363342 | K8: =ROUND(AVERAGE(RawData!G2:G10000),1) -> 76.9
B10: 📈 CHARTS & DEEP ANALYSIS

Sheet Interactive Controls
B2: 🎛️ INTERACTIVE CONTROLS & DYNAMIC LOOKUP
B5: 🔍 MOVIE LOOKUP — Select a movie to see full details
B7: Select Movie: | C7: Ghostbusters
B9: Released Year | C9: =IF($C$7="","",IFERROR(INDEX(RawData!$B$2:$B$10000,MATCH($C$7,RawData!$A$2:$A$10000,0)),"Not found")) -> 1984
B10: Certificate | C10: =IF($C$7="","",IFERROR(INDEX(RawData!$C$2:$C$10000,MATCH($C$7,RawData!$A$2:$A$10000,0)),"Not found")) -> UA
B11: Runtime | C11: =IF($C$7="","",IFERROR(INDEX(RawData!$D$2:$D$10000,MATCH($C$7,RawData!$A$2:$A$10000,0)),"Not found")) -> 105 min
B12: Genre | C12: =IF($C$7="","",IFERROR(INDEX(RawData!$E$2:$E$10000,MATCH($C$7,RawData!$A$2:$A$10000,0)),"Not found")) -> Action, Comedy, Fantasy
B13: IMDB Rating | C13: =IF($C$7="","",IFERROR(INDEX(RawData!$F$2:$F$10000,MATCH($C$7,RawData!$A$2:$A$10000,0)),"Not found")) -> 7.8
B14: Meta Score | C14: =IF($C$7="","",IFERROR(INDEX(RawData!$G$2:$G$10000,MATCH($C$7,RawData!$A$2:$A$10000,0)),"Not found")) -> 71
B15: Director | C15: =IF($C$7="","",IFERROR(INDEX(RawData!$H$2:$H$10000,MATCH($C$7,RawData!$A$2:$A$10000,0)),"Not found")) -> Ivan Reitman
B16: Star 1 | C16: =IF($C$7="","",IFERROR(INDEX(RawData!$I$2:$I$10000,MATCH($C$7,RawData!$A$2:$A$10000,0)),"Not found")) -> Bill Murray
B17: Star 2 | C17: =IF($C$7="","",IFERROR(INDEX(RawData!$J$2:$J$10000,MATCH($C$7,RawData!$A$2:$A$10000,0)),"Not found")) -> Dan Aykroyd
B18: No. of Votes | C18: =IF($C$7="","",IFERROR(INDEX(RawData!$M$2:$M$10000,MATCH($C$7,RawData!$A$2:$A$10000,0)),"Not found")) -> 355413
B19: Gross Revenue ($) | C19: =IF($C$7="","",IFERROR(INDEX(RawData!$N$2:$N$10000,MATCH($C$7,RawData!$A$2:$A$10000,0)),"Not found")) -> 238632124
B22: 🎬 DIRECTOR STATS — Select a director
B24: Select Director: | C24: Taylor Hackford
B26: Total Movies Directed | C26: =COUNTIF(RawData!$H$2:$H$10000,$C$24) -> 2
B27: Avg IMDB Rating | C27: =IFERROR(ROUND(AVERAGEIF(RawData!$H$2:$H$10000,$C$24,RawData!$F$2:$F$10000),2),"N/A") -> 7.85
B28: Total Gross Revenue | C28: =IFERROR(SUMIF(RawData!$H$2:$H$10000,$C$24,RawData!$N$2:$N$10000),"N/A") -> 79828183
B29: Avg Gross per Movie | C29: =IFERROR(ROUND(AVERAGEIF(RawData!$H$2:$H$10000,$C$24,RawData!$N$2:$N$10000),0),"N/A") -> 39914092
B30: Highest Rated Movie | C30: =IFERROR(INDEX(RawData!$A$2:$A$10000,MATCH(_xlfn.MAXIFS(RawData!$F$2:$F$10000,RawData!$H$2:$H$10000,$C$24),RawData!$F$2:$F$10000,0)),"Not Found") -> Tropa de Elite
B33: 📅 YEAR FILTER — Movies released in selected year
B35: Select Year: | C35: 2006
B37: Movies in Selected Year | C37: =COUNTIF(RawData!$B$2:$B$10000,TEXT($C$35,"0")) -> 20
B38: Avg Rating (that year) | C38: =IFERROR(ROUND(AVERAGEIF(RawData!$B$2:$B$10000,TEXT($C$35,"0"),RawData!$F$2:$F$10000),2),"N/A") -> 7.88
B39: Total Gross (that year) | C39: =IFERROR(SUMIF(RawData!$B$2:$B$10000,TEXT($C$35,"0"),RawData!$N$2:$N$10000),"N/A") -> 1156908937
B40: Top Movie (that year) | C40: =IFERROR(INDEX(RawData!$A$2:$A$10000,MATCH(_xlfn.MAXIFS(RawData!$F$2:$F$10000,RawData!$B$2:$B$10000,TEXT($C$35,"0")),RawData!$F$2:$F$10000,0)),"Not Found") -> The Intouchables

Sheet RawData
A1: Movie Title | B1: Year | C1: Certificate | D1: Runtime | E1: Genre | F1: IMDB Rating | G1: Meta Score | H1: Director | I1: Star 1 | J1: Star 2 | K1: Star 3 | L1: Star 4 | M1: No. of Votes | N1: Gross ($) | O1: Runtime (min) | P1: Primary Genre
A2: I Am Sam | B2: 2001 | C2: PG-13 | D2: 132 min | E2: Drama | F2: 7.7 | G2: 28 | H2: Jessie Nelson | I2: Sean Penn | J2: Michelle Pfeiffer | K2: Dakota Fanning | L2: Dianne Wiest | M2: 142863 | N2: 40311852 | O2: 132 | P2: Drama
A3: The Butterfly Effect | B3: 2004 | C3: U | D3: 113 min | E3: Drama, Sci-Fi, Thriller | F3: 7.6 | G3: 30 | H3: Eric Bress | I3: J. Mackye Gruber | J3: Ashton Kutcher | K3: Amy Smart | L3: Melora Walters | M3: 451479 | N3: 57938693 | O3: 113 | P3: Drama
A4: Tropa de Elite | B4: 2007 | C4: R | D4: 115 min | E4: Action, Crime, Drama | F4: 8 | G4: 33 | H4: José Padilha | I4: Wagner Moura | J4: André Ramiro | K4: Caio Junqueira | L4: Milhem Cortaz | M4: 98097 | N4: 8060 | O4: 115 | P4: Action
A5: Seven Pounds | B5: 2008 | C5: UA | D5: 123 min | E5: Drama | F5: 7.6 | G5: 36 | H5: Gabriele Muccino | I5: Will Smith | J5: Rosario Dawson | K5: Woody Harrelson | L5: Michael Ealy | M5: 286770 | N5: 69951824 | O5: 123 | P5: Drama
A6: Kai po che! | B6: 2013 | C6: U | D6: 130 min | E6: Drama, Sport | F6: 7.7 | G6: 40 | H6: Abhishek Kapoor | I6: Amit Sadh | J6: Sushant Singh Rajput | K6: Rajkummar Rao | L6: Amrita Puri | M6: 32628 | N6: 1122527 | O6: 130 | P6: Drama
A7: Fear and Loathing in Las Vegas | B7: 1998 | C7: R | D7: 118 min | E7: Adventure, Comedy, Drama | F7: 7.6 | G7: 41 | H7: Terry Gilliam | I7: Johnny Depp | J7: Benicio Del Toro | K7: Tobey Maguire | L7: Michael Lee Gogin | M7: 259753 | N7: 10680275 | O7: 118 | P7: Adventure
A8: Flipped | B8: 2010 | C8: PG | D8: 90 min | E8: Comedy, Drama, Romance | F8: 7.7 | G8: 45 | H8: Rob Reiner | I8: Madeline Carroll | J8: Callan McAuliffe | K8: Rebecca De Mornay | L8: Anthony Edwards | M8: 81446 | N8: 1752214 | O8: 90 | P8: Comedy
A9: Jeux d'enfants | B9: 2003 | C9: R | D9: 93 min | E9: Comedy, Drama, Romance | F9: 7.6 | G9: 45 | H9: Yann Samuell | I9: Guillaume Canet | J9: Marion Cotillard | K9: Thibault Verhaeghe | L9: Joséphine Lebas-Joly | M9: 67360 | N9: 548707 | O9: 93 | P9: Comedy
A10: Predator | B10: 1987 | C10: A | D10: 107 min | E10: Action, Adventure, Sci-Fi | F10: 7.8 | G10: 45 | H10: John McTiernan | I10: Arnold Schwarzenegger | J10: Carl Weathers | K10: Kevin Peter Hall | L10: Elpidia Carrillo | M10: 371387 | N10: 59735548 | O10: 107 | P10: Action
A11: Saw | B11: 2004 | C11: UA | D11: 103 min | E11: Horror, Mystery, Thriller | F11: 7.6 | G11: 46 | H11: James Wan | I11: Cary Elwes | J11: Leigh Whannell | K11: Danny Glover | L11: Ken Leung | M11: 379020 | N11: 56000369 | O11: 103 | P11: Horror
A12: Bound by Honor | B12: 1993 | C12: R | D12: 180 min | E12: Crime, Drama | F12: 8 | G12: 47 | H12: Taylor Hackford | I12: Damian Chapa | J12: Jesse Borrego | K12: Benjamin Bratt | L12: Enrique Castillo | M12: 28825 | N12: 4496583 | O12: 180 | P12: Crime
A13: Man on Fire | B13: 2004 | C13: UA | D13: 146 min | E13: Action, Crime, Drama | F13: 7.7 | G13: 47 | H13: Tony Scott | I13: Denzel Washington | J13: Christopher Walken | K13: Dakota Fanning | L13: Radha Mitchell | M13: 329592 | N13: 77911774 | O13: 146 | P13: Action
... A674: Fanny och Alexander | B674: 1982 | C674: A | D674: 188 min | E674: Drama | F674: 8.1 | G674: 100 | H674: Ingmar Bergman | I674: Bertil Guve | J674: Pernilla Allwin | K674: Kristina Adolphson | L674: Börje Ahlstedt | M674: 57784 | N674: 4971340 | O674: 188 | P674: Drama

Sheet _HelperData
A1: Genre Distribution
A2: Genre | B2: Count
A3: Drama | B3: 474
A4: Adventure | B4: 156
A5: Comedy | B5: 154
A6: Action | B6: 134
A7: Crime | B7: 134
A8: Thriller | B8: 93
A9: Biography | B9: 85
A10: Romance | B10: 83
A11: Mystery | B11: 63
A12: Animation | B12: 58
A13: Sci-Fi | B13: 54
A14: Fantasy | B14: 52
A15: Rating Distribution
A16: Rating Range | B16: Count
A17: 7.5-7.8 | B17: 315
A18: 7.8-8.0 | B18: 166
A19: 8.0-8.2 | B19: 96
A20: 8.2-8.4 | B20: 51
A21: 8.4-8.6 | B21: 27
A22: 8.6-8.8 | B22: 10
A23: 8.8-9.0 | B23: 6
A24: 9.0-9.5 | B24: 2
A25: Year Distribution
A26: Year | B26: Count
A27: 1980 | B27: 6
A28: 1981 | B28: 4
A29: 1982 | B29: 8
A30: 1983 | B30: 4
A31: 1984 | B31: 8
A32: 1985 | B32: 8
A33: 1986 | B33: 8
A34: 1987 | B34: 12
A35: 1988 | B35: 6
A36: 1989 | B36: 9
A37: 1990 | B37: 8
A38: 1991 | B38: 11
... A66: 2019 | B66: 14
A67: Top 10 by Rating
...

Sheet _ScatterData
A1: IMDB Rating | B1: Meta Score
A2: 7.7 | B2: 28
A3: 7.6 | B3: 30
A4: 8 | B4: 33
A5: 7.6 | B5: 36
A6: 7.7 | B6: 40
A7: 7.6 | B7: 41
A8: 7.7 | B8: 45
A9: 7.6 | B9: 45
A10: 7.8 | B10: 45
A11: 7.6 | B11: 46
A12: 8 | B12: 47
A13: 7.7 | B13: 47
... A101: 7.8 | B101: 65
